Workbook
Name TierList: Parametros!$A$31:$A$33
Name OfertaList: Parametros!$B$31:$B$33
Name CompetenciaList: Parametros!$C$31:$C$33
Name SiNoList: Parametros!$D$31:$D$32
Name SiParcialNoList: Parametros!$E$31:$E$33
Name MarcaList: Parametros!$F$31:$F$33
Name FinanciacionList: Parametros!$G$31:$G$33

Sheet Simulador
A1: Simulador de pipeline — Piloto implantología SyM x Climadent
A2: Rellena las celdas amarillas. Cada variable impacta únicamente en su fase real del embudo.
A4: INPUTS GENERALES | D4: CÁLCULOS | G4: PIPELINE RESULTANTE
A5: Inversión diaria (€) | B5: 15 | D5: CPL base tier | E5: =VLOOKUP(B10,Parametros!A4:C6,2,FALSE) | G5: Fase | H5: KPI | I5: Resultado | J5: Lectura
A6: Días activos/mes | B6: 30 | D6: Ajuste oferta | E6: =VLOOKUP(B11,Parametros!E4:G6,2,FALSE) | G6: Captación | H6: CPL final | I6: =E8 | J6: Coste medio por lead
A7: Inversión mensual (€) | B7: =B5*B6 | D7: Ajuste competencia | E7: =VLOOKUP(B12,Parametros!I4:J6,2,FALSE) | G7: Captación | H7: Leads generados | I7: =B7/E8 | J7: Volumen estimado mensual
A8: Ticket medio por paciente (€) | B8: 5000 | D8: CPL final | E8: =D5*D6*D7 | G8: Contacto | H8: % contactados | I8: =E9 | J8: Impacta rapidez + protocolo + marca
A9: Implantes medios por paciente | B9: 3 | D9: % contacto | E9: =MIN(0.95,SUMIFS(Parametros!C11:C19,Parametros!A11:A19,"Base contacto",Parametros!B11:B19,"Base")+SUMIFS(Parametros!C11:C19,Parametros!A11:A19,A16,Parametros!B11:B19,B16)+SUMIFS(Parametros!C11:C19,Parametros!A11:A19,A17,Parametros!B11:B19,B17)+SUMIFS(Parametros!C11:C19,Parametros!A11:A19,A18,Parametros!B11:B19,B18)) | G9: Contacto | H9: Leads contactados | I9: =I7*I8 | J9: Personas con conversación real
A10: Tier geográfico | B10: Tier 2 - capital secundaria | D10: % cita/contacto | E10: =MIN(0.90,SUMIFS(Parametros!G11:G17,Parametros!E11:E17,"Base agendado",Parametros!F11:F17,"Base")+SUMIFS(Parametros!G11:G17,Parametros!E11:E17,A22,Parametros!F11:F17,B22)+SUMIFS(Parametros!G11:G17,Parametros!E11:E17,A23,Parametros!F11:F17,B23)) | G10: Agendado | H10: % cita/contacto | I10: =E10 | J10: Impacta recepción + script
A11: Oferta/campaña | B11: Media | D11: % asistencia | E11: =MIN(0.90,SUMIFS(Parametros!K11:K19,Parametros!I11:I19,"Base asistencia",Parametros!J11:J19,"Base")+SUMIFS(Parametros!K11:K19,Parametros!I11:I19,A27,Parametros!J11:J19,B27)+SUMIFS(Parametros!K11:K19,Parametros!I11:I19,A28,Parametros!J11:J19,B28)+SUMIFS(Parametros!K11:K19,Parametros!I11:I19,A29,Parametros!J11:J19,B29)) | G11: Agendado | H11: Citas agendadas | I11: =I9*I10 | J11: Citas generadas
A12: Competencia local | B12: Media | D12: % cierre/visita | E12: =MIN(0.55,SUMIFS(Parametros!O11:O21,Parametros!M11:M21,"Base cierre",Parametros!N11:N21,"Base")+SUMIFS(Parametros!O11:O21,Parametros!M11:M21,A34,Parametros!N11:N21,B34)+SUMIFS(Parametros!O11:O21,Parametros!M11:M21,A35,Parametros!N11:N21,B35)+SUMIFS(Parametros!O11:O21,Parametros!M11:M21,A36,Parametros!N11:N21,B36)+SUMIFS(Parametros!O11:O21,Parametros!M11:M21,A37,Parametros!N11:N21,B37)) | G12: Asistencia | H12: % asistencia | I12: =E11 | J12: Impacta recordatorios + seguimiento + autoridad
G13: Asistencia | H13: Primeras visitas | I13: =I11*I12 | J13: Visitas reales
G14: Cierre | H14: % cierre/visita | I14: =E12 | J14: Impacta diagnóstico + financiación + asesor + PV
A15: FASE 2 · CONTACTO | G15: Cierre | H15: % cierre sobre leads | I15: =I14*I12*I10*I8 | J15: Conversión total del embudo
A16: Contacto en el día | B16: Sí | G16: Cierre | H16: Pacientes cerrados | I16: =I7*I15 | J16: Tratamientos iniciados
A17: Protocolo llamada Climadent | B17: Sí | G17: Impacto SyM | H17: Implantes estimados | I17: =I16*B9 | J17: Consumo directo estimado para SyM
A18: Marca/Instagram/Web | B18: Correcta | G18: Impacto económico | H18: Ingresos clínica | I18: =I16*B8 | J18: Facturación estimada
G19: Impacto económico | H19: CAC por paciente | I19: =IF(I16>0,B7/I16,0) | J19: Coste adquisición paciente
G20: Impacto económico | H20: ROI sobre inversión | I20: =IF(B7>0,I18/B7,0) | J20: Ingresos / inversión
A21: FASE 3 · AGENDADO
A22: Recepción formada | B22: Sí
A23: Script de cita | B23: Sí
A26: FASE 4 · ASISTENCIA
A27: Recordatorios | B27: Sí
A28: Formación seguimiento | B28: Sí
A29: Autoridad digital | B29: Correcta
A33: FASE 5 · CIERRE
A34: TAC/diagnóstico | B34: Sí
A35: Financiación | B35: Buenas
A36: Asesor comercial | B36: Sí
A37: Protocolo primera visita | B37: Sí
A41: Mapa de impacto de variables por fase
A42: Variable | B42: Captación | C42: Contacto | D42: Agendado | E42: Asistencia | F42: Cierre | G42: Motivo
A43: Tier geográfico | B43: Sí | G43: Afecta al CPL y al volumen de leads por competencia y tamaño de mercado
A44: Oferta/campaña | B44: Sí | G44: Afecta a la respuesta del anuncio y al coste por lead
A45: Competencia local | B45: Sí | G45: Afecta al coste de captar atención
A46: Contacto en el día | C46: Sí | G46: Afecta a la probabilidad de hablar con el lead
A47: Marca/Instagram/Web | C47: Sí | E47: Sí | G47: Aumenta confianza antes de responder y reduce fricción para acudir
A48: Recepción formada | D48: Sí | G48: Convierte conversaciones en citas
A49: Script de cita | D49: Sí | G49: Mejora gestión de objeciones iniciales
...

Sheet Parametros
A1: Tablas de parámetros del simulador
A3: Tier geográfico | B3: CPL base | C3: Nota | E3: Oferta/campaña | F3: Ajuste CPL | G3: Nota | I3: Competencia local | J3: Ajuste CPL
A4: Tier 1 - Madrid/Barcelona/Valencia | B4: 10.5 | C4: Mercados grandes: más competencia y menor volumen por euro | E4: Básica | F4: 1.1 | G4: Oferta menos diferencial | I4: Alta | J4: 1.15
A5: Tier 2 - capital secundaria | B5: 6 | C5: Buen equilibrio entre volumen y calidad | E5: Media | F5: 1 | G5: Oferta estándar defendible | I5: Media | J5: 1
A6: Tier 3 - ciudad pequeña/rural | B6: 4.5 | C6: Mejor rendimiento habitual en captación | E6: Fuerte | F6: 0.9 | G6: Oferta más atractiva / mayor respuesta | I6: Baja | J6: 0.9
A9: Contacto | E9: Agendado | I9: Asistencia | M9: Cierre
A10: Variable | B10: Opción | C10: Impacto | E10: Variable | F10: Opción | G10: Impacto | I10: Variable | J10: Opción | K10: Impacto | M10: Variable | N10: Opción | O10: Impacto
A11: Base contacto | B11: Base | C11: 0.65 | E11: Base agendado | F11: Base | G11: 0.55 | I11: Base asistencia | J11: Base | K11: 0.5 | M11: Base cierre | N11: Base | O11: 0.18
A12: Contacto en el día | B12: Sí | C12: 0.12 | E12: Recepción formada | F12: Sí | G12: 0.12 | I12: Recordatorios | J12: Sí | K12: 0.1 | M12: TAC/diagnóstico | N12: Sí | O12: 0.08
A13: Contacto en el día | B13: No | C13: 0 | E13: Recepción formada | F13: Parcial | G13: 0.06 | I13: Recordatorios | J13: Parcial | K13: 0.05 | M13: TAC/diagnóstico | N13: Parcial | O13: 0.04
A14: Protocolo llamada Climadent | B14: Sí | C14: 0.07 | E14: Recepción formada | F14: No | G14: 0 | I14: Recordatorios | J14: No | K14: 0 | M14: TAC/diagnóstico | N14: No | O14: 0
A15: Protocolo llamada Climadent | B15: Parcial | C15: 0.03 | E15: Script de cita | F15: Sí | G15: 0.08 | I15: Formación seguimiento | J15: Sí | K15: 0.08 | M15: Financiación | N15: Buenas | O15: 0.08
A16: Protocolo llamada Climadent | B16: No | C16: 0 | E16: Script de cita | F16: Parcial | G16: 0.04 | I16: Formación seguimiento | J16: Parcial | K16: 0.04 | M16: Financiación | N16: Limitadas | O16: 0.03
A17: Marca/Instagram/Web | B17: Fuerte | C17: 0.06 | E17: Script de cita | F17: No | G17: 0 | I17: Formación seguimiento | J17: No | K17: 0 | M17: Financiación | N17: No | O17: 0
A18: Marca/Instagram/Web | B18: Correcta | C18: 0.03 | I18: Autoridad digital | J18: Fuerte | K18: 0.07 | M18: Asesor comercial | N18: Sí | O18: 0.08
A19: Marca/Instagram/Web | B19: Débil | C19: 0 | I19: Autoridad digital | J19: Correcta | K19: 0.03 | M19: Asesor comercial | N19: No | O19: 0
I20: Autoridad digital | J20: Débil | K20: 0 | M20: Protocolo primera visita | N20: Sí | O20: 0.1
M21: Protocolo primera visita | N21: Parcial | O21: 0.05
M22: Protocolo primera visita | N22: No | O22: 0
A30: TierList | B30: OfertaList | C30: CompetenciaList | D30: SiNoList | E30: SiParcialNoList | F30: MarcaList | G30: FinanciacionList
A31: Tier 1 - Madrid/Barcelona/Valencia | B31: Básica | C31: Alta | D31: Sí | E31: Sí | F31: Débil | G31: Buenas
A32: Tier 2 - capital secundaria | B32: Media | C32: Media | D32: No | E32: Parcial | F32: Correcta | G32: Limitadas
A33: Tier 3 - ciudad pequeña/rural | B33: Fuerte | C33: Baja | E33: No | F33: Fuerte | G33: No

Sheet Benchmark
A1: Benchmark de escenarios automáticos
A2: Comparativa orientativa con inversión mensual de 450€ y ticket medio de 5.000€.
A4: Escenario | B4: Tier | C4: Tipo clínica | D4: CPL | E4: Leads | F4: % contacto | G4: % cita | H4: % asistencia | I4: % cierre/visita | J4: % cierre/lead | K4: Pacientes | L4: Implantes | M4: Ingresos
A5: Tier 1 clínica débil | B5: Tier 1 | C5: Con margen de mejora | D5: 11.5 | E5: 39.130435 | F5: 0.65 | G5: 0.55 | H5: 0.5 | I5: 0.22 | J5: 0.039325 | K5: 1.5388043 | L5: 4.616413 | M5: 7694.0217
A6: Tier 1 clínica fuerte | B6: Tier 1 | C6: Estructurada | D6: 9.5 | E6: 47.368421 | F6: 0.82 | G6: 0.72 | H6: 0.68 | I6: 0.38 | J6: 0.15255936 | K6: 7.226496 | L6: 21.679488 | M6: 36132.48
A7: Tier 2 clínica media | B7: Tier 2 | C7: Media | D7: 6 | E7: 75 | F7: 0.78 | G7: 0.68 | H7: 0.63 | I7: 0.3 | J7: 0.1002456 | K7: 7.51842 | L7: 22.55526 | M7: 37592.1
A8: Tier 3 clínica fuerte | B8: Tier 3 | C8: Estructurada | D8: 4.5 | E8: 100 | F8: 0.85 | G8: 0.75 | H8: 0.7 | I8: 0.4 | J8: 0.1785 | K8: 17.85 | L8: 53.55 | M8: 89250

Sheet Diccionario
A1: Diccionario de lectura del modelo
A3: Concepto | B3: Explicación
A4: CPL | B4: Coste por persona interesada que deja sus datos. Depende de tier, oferta y competencia.
A5: % contacto | B5: Porcentaje de leads con los que la clínica consigue hablar. Depende de contacto en el día, protocolo y autoridad previa.
A6: % cita/contacto | B6: Porcentaje de contactados que aceptan una primera visita. Depende de recepción y script.
A7: % asistencia | B7: Porcentaje de citas que acuden. Depende de recordatorios, seguimiento y confianza.
A8: % cierre/visita | B8: Porcentaje de primeras visitas que empiezan tratamiento. Depende de diagnóstico, financiación, asesor y protocolo de primera visita.
A9: % cierre/lead | B9: Conversión total del embudo: contacto × cita × asistencia × cierre.
A10: Implantes estimados | B10: Pacientes cerrados × implantes medios por paciente. Es el KPI directo para Sweden & Martina.
